Workbook

Sheet Savings comparison
A1: Savings Calculation Template
A2: Client-facing template comparing the current position with RB service options. P&L tab remains an add-on after the client chooses an option.
A4: Metric | B4: Before analysis | C4: Option 1 - Basic operating entity | D4: Option 2 - Full optimisation | E4: Option 3 - Pension reserve | F4: Option 4 - IE tax residence
A5: Service scope | B5: Current position | C5: Basic operating entity; no optimisation | D5: Full optimisation excl. pension reserve | E5: Full optimisation + pension reserve | F5: IE tax residence + director support
A6: Tax residence | B6: =Assumptions!$B$11 -> DE | C6: DE | D6: DE | E6: DE | F6: IE
A7: Optimises office rent | B7: No | C7: No | D7: Yes | E7: Yes | F7: Yes
A8: Optimises business travel / other expenses | B8: No | C8: No | D8: Yes | E8: Yes | F8: Yes
A9: Car depreciation support | B9: No | C9: No | D9: Yes | E9: Yes | F9: Yes
A10: Investment planning support | B10: No | C10: No | D10: Yes | E10: Yes | F10: Yes
A11: Pension reserve included | B11: No | C11: No | D11: No | E11: Yes | F11: No
A12: Director fee required | B12: No | C12: No | D12: No | E12: No | F12: Yes
A13: Previous accounting fee | B13: =Assumptions!$B$49 -> 0 | C13: =Assumptions!$B$49 -> 0 | D13: =Assumptions!$B$49 -> 0 | E13: =Assumptions!$B$49 -> 0 | F13: =Assumptions!$B$49 -> 0
A14: RB Accounting, Legal, Structuring | B14: 0 | C14: =Assumptions!$B$50 -> 500 | D14: =Assumptions!$B$51 -> 1000 | E14: =Assumptions!$B$51 -> 1000 | F14: =Assumptions!$B$51 -> 1000
A15: Employee surcharge | B15: 0 | C15: 0 | D15: =IF(Assumptions!$B$9>Assumptions!$B$52,Assumptions!$B$53,0) -> 0 | E15: =IF(Assumptions!$B$9>Assumptions!$B$52,Assumptions!$B$53,0) -> 0 | F15: =IF(Assumptions!$B$9>Assumptions!$B$52,Assumptions!$B$53,0) -> 0
A16: Pension surcharge | B16: 0 | C16: 0 | D16: 0 | E16: =Assumptions!$B$54 -> 200 | F16: 0
A17: Dual tax jurisdiction surcharge | B17: 0 | C17: 0 | D17: 0 | E17: 0 | F17: =Assumptions!$B$55 -> 200
A18: Director surcharge (discounted) | B18: 0 | C18: 0 | D18: 0 | E18: 0 | F18: =Assumptions!$B$56 -> 400
A19: Total RB fee | B19: 0 | C19: =SUM(C14:C18) -> 500 | D19: =SUM(D14:D18) -> 1000 | E19: =SUM(E14:E18) -> 1200 | F19: =SUM(F14:F18) -> 1600
A21: Company model
A22: Estimated status quo profit | B22: =Assumptions!$B$24 -> 120000 | C22: =Assumptions!$B$24 -> 120000 | D22: =Assumptions!$B$24 -> 120000 | E22: =Assumptions!$B$24 -> 120000 | F22: =Assumptions!$B$24 -> 120000
A23: Office rent deductible | B23: 0 | C23: 0 | D23: =Assumptions!$B$29 -> 0 | E23: =Assumptions!$B$29 -> 0 | F23: =Assumptions!$B$29 -> 0
A24: Business travel / other deductible | B24: 0 | C24: 0 | D24: =Assumptions!$B$31+Assumptions!$B$32 -> 0 | E24: =Assumptions!$B$31+Assumptions!$B$32 -> 0 | F24: =Assumptions!$B$31+Assumptions!$B$32 -> 0
A25: Other investment planning benefit | B25: 0 | C25: 0 | D25: =Assumptions!$B$42 -> 0 | E25: =Assumptions!$B$42 -> 0 | F25: =Assumptions!$B$42 -> 0
A26: Annual car depreciation deductible | B26: 0 | C26: 0 | D26: =Assumptions!$B$39 -> 0 | E26: =Assumptions!$B$39 -> 0 | F26: =Assumptions!$B$39 -> 0
A27: Pension reserve contribution | B27: 0 | C27: 0 | D27: 0 | E27: =Assumptions!$B$43 -> 0 | F27: 0
A28: IE director fee deductible | B28: 0 | C28: 0 | D28: 0 | E28: 0 | F28: =Assumptions!$B$46 -> 0
A29: RB fee deductible | B29: 0 | C29: =C19 -> 500 | D29: =D19 -> 1000 | E29: =E19 -> 1200 | F29: =F19 -> 1600
A30: Total additional deductions | B30: =SUM(B23:B29) -> 0 | C30: =SUM(C23:C29) -> 500 | D30: =SUM(D23:D29) -> 1000 | E30: =SUM(E23:E29) -> 1200 | F30: =SUM(F23:F29) -> 1600
A31: Estimated taxable profit after scenario | B31: =MAX(0,B22-B30) -> 120000 | C31: =MAX(0,C22-C30) -> 119500 | D31: =MAX(0,D22-D30) -> 119000 | E31: =MAX(0,E22-E30) -> 118800 | F31: =MAX(0,F22-F30) -> 118400
A32: Corporation tax rate | B32: =Assumptions!$B$15 -> 0.3 | C32: =Assumptions!$B$15 -> 0.3 | D32: =Assumptions!$B$15 -> 0.3 | E32: =Assumptions!$B$15 -> 0.3 | F32: =Assumptions!$B$16 -> 0.125
A33: Corporation tax payable | B33: =B31*B32 -> 36000 | C33: =C31*C32 -> 35850 | D33: =D31*D32 -> 35700 | E33: =E31*E32 -> 35640 | F33: =F31*F32 -> 14800
A34: Corporation tax saved vs before | B34: 0 | C34: =$B$33-C33 -> 150 | D34: =$B$33-D33 -> 300 | E34: =$B$33-E33 -> 360 | F34: =$B$33-F33 -> 21200
A36: Personal / owner value
A37: Office rent net owner benefit | B37: 0 | C37: =C23*(1-Assumptions!$B$17*Assumptions!$B$30) -> 0 | D37: =D23*(1-Assumptions!$B$17*Assumptions!$B$30) -> 0 | E37: =E23*(1-Assumptions!$B$17*Assumptions!$B$30) -> 0 | F37: =F23*(1-Assumptions!$B$17*Assumptions!$B$30) -> 0
A38: Travel / other costs shifted from personal | B38: 0 | C38: =C24 -> 0 | D38: =D24 -> 0 | E38: =E24 -> 0 | F38: =F24 -> 0
A39: Investment planning benefit | B39: 0 | C39: =C25 -> 0 | D39: =D25 -> 0 | E39: =E25 -> 0 | F39: =F25 -> 0
A40: Pension reserve value | B40: 0 | C40: =C27 -> 0 | D40: =D27 -> 0 | E40: =E27 -> 0 | F40: =F27 -> 0
A41: Director fee net owner benefit | B41: 0 | C41: =C28*(1-Assumptions!$B$47) -> 0 | D41: =D28*(1-Assumptions!$B$47) -> 0 | E41: =E28*(1-Assumptions!$B$47) -> 0 | F41: =F28*(1-Assumptions!$B$47) -> 0
A43: Outcome
A44: Incremental value before RB fee | B44: 0 | C44: =C34+SUM(C37:C41) -> 150 | D44: =D34+SUM(D37:D41) -> 300 | E44: =E34+SUM(E37:E41) -> 360 | F44: =F34+SUM(F37:F41) -> 21200
...

Sheet Assumptions
A1: Assumptions
A2: Status: provisional. Source: user instruction, RB internal service lists, and public DE pricing references imported 2026-06-12. Review before client reliance.
A4: Input | B4: Value | C4: Unit | D4: Notes
A5: Client / company name | C5: text | D5: Client-facing display name
A6: Prepared for | C6: text | D6: Contact or stakeholder
A8: Selected scenario | B8: Client choice pending | C8: choice | D8: P&L add-on stays pending until a client choice is made
A9: Total employees | B9: 1 | C9: count | D9: Employee surcharge applies above the threshold below
A10: Employee notes | C10: text | D10: Use for part-time or payroll complexity notes
A11: Current tax residence | B11: DE | C11: choice | D11: Option 4 models IE tax residence
A13: Tax rates
A14: Tax rate note | B14: Replace rates with client-specific values | C14: text | D14: Planning rates only
A15: DE corporation tax rate | B15: 0.3 | C15: % incl. trade tax | D15: Planning assumption; replace with client-specific rate
A16: IE corporation tax rate | B16: 0.125 | C16: % | D16: Trading-rate planning assumption; confirm applicability
A17: Owner marginal personal tax rate | B17: 0.42 | C17: % | D17: Review-only rate used for net owner benefit estimates; not a client data input
A19: Operating model
A20: Operating model note | B20: Status quo estimated from earnings and spend | C20: text | D20: Future gross-net calculator workflow can use https://www.brutto-netto-rechner.info/gehalt/gehaltsrechner-arbeitgeber.php
A21: Annual revenue | B21: 180000 | C21: EUR | D21: Before optimisation
A22: Current operating costs before owner planning | B22: 60000 | C22: EUR | D22: Exclude RB fee and optimisation items below
A23: Baseline profit already includes current accounting fee? | B23: No | C23: text | D23: Set previous accounting fee below to 0 if already embedded and not replaced
A24: Estimated status quo profit (calculated) | B24: =B21-B22 -> 120000 | C24: EUR | D24: Calculated from annual revenue minus current operating costs; not a client input
A26: Office rent and expense optimisation
A27: Office rent note | B27: Use conservative eligible amounts | C27: text | D27: Company-paid office rent or home-office arrangement
A28: Annual office rent company can rent to owner | B28: 0 | C28: EUR | D28: Company-paid office rent or home-office arrangement
A29: Eligible office rent deductible | B29: =B28 -> 0 | C29: EUR | D29: Used in comparison tab
A30: Taxable share of company-paid office rent | B30: 0.5 | C30: % | D30: Use 0 if tax-free and 1 if fully taxable to the owner; review case by case
A31: Business travel deductible | B31: 0 | C31: EUR | D31: Business travel moved into company
A32: Other eligible business expenses deductible | B32: 0 | C32: EUR | D32: Software, training, conferences, equipment, etc.
A34: Car purchase / depreciation
A35: Car purchase price | B35: 0 | C35: EUR | D35: Gross planning amount
A36: Useful life years | B36: 5 | C36: years | D36: Replace with client-specific depreciation method
A37: Business-use share | B37: 0.8 | C37: % | D37: Planning share
A38: Annual depreciation before business-use share | B38: =IF(B36>0,B35/B36,0) -> 0 | C38: EUR | D38: Straight-line placeholder
A39: Eligible annual car depreciation | B39: =B38*B37 -> 0 | C39: EUR | D39: Used in comparison tab
A41: Investment and pension reserve
A42: Other investment planning benefit | B42: 0 | C42: EUR | D42: Retained-profit or investment planning value
A43: Pension reserve contribution | B43: 0 | C43: EUR | D43: Only included in Option 3
A45: IE tax residence / director
A46: Annual director fee deductible | B46: 0 | C46: EUR | D46: Only included in Option 4
A47: Estimated tax on director fee | B47: 0.2 | C47: % | D47: Applied to director fee only to estimate after-tax owner benefit; review case by case
A49: Previous accounting fee | B49: 0 | C49: EUR | D49: Current annual accounting, legal, or advisory fee that RB replaces
...

Sheet P&L - add-on
A1: P&L - add-on
A2: Use this tab only after the client has chosen an option. It is a monthly planning view, not a replacement for the savings comparison.
A3: Selected option | B3: =Assumptions!$B$8 -> Client choice pending
A4: Annual net savings after fee | B4: {=IFERROR(INDEX('Savings comparison'!$C$46:$F$46,1,MATCH($B$3,'Savings comparison'!$C$4:$F$4,0)),"")}
A6: Line item | B6: Annual / source | C6: Month 1 | D6: Month 2 | E6: Month 3 | F6: Month 4 | G6: Month 5 | H6: Month 6 | I6: Month 7 | J6: Month 8 | K6: Month 9 | L6: Month 10 | M6: Month 11 | N6: Month 12
A7: Revenue | B7: Assumptions!B21 | C7: {=Assumptions!$B$21/12+COLUMN(C6:N6)*0} -> 15000 | D7: 15000 | E7: 15000 | F7: 15000 | G7: 15000 | H7: 15000 | I7: 15000 | J7: 15000 | K7: 15000 | L7: 15000 | M7: 15000 | N7: 15000
A8: Existing operating costs | B8: Assumptions!B22 | C8: {=Assumptions!$B$22/12+COLUMN(C6:N6)*0} -> 5000 | D8: 5000 | E8: 5000 | F8: 5000 | G8: 5000 | H8: 5000 | I8: 5000 | J8: 5000 | K8: 5000 | L8: 5000 | M8: 5000 | N8: 5000
A9: Previous accounting fee avoided | B9: Assumptions!B49 | C9: {=Assumptions!$B$49/12+COLUMN(C6:N6)*0} -> 0 | D9: 0 | E9: 0 | F9: 0 | G9: 0 | H9: 0 | I9: 0 | J9: 0 | K9: 0 | L9: 0 | M9: 0 | N9: 0
A10: Office rent paid by company | B10: Selected option | C10: {=IFERROR(INDEX('Savings comparison'!$C$23:$F$23,1,MATCH($B$3,'Savings comparison'!$C$4:$F$4,0))/12+COLUMN(C6:N6)*0,"")}
A11: Business travel / other expenses | B11: Selected option | C11: {=IFERROR(INDEX('Savings comparison'!$C$24:$F$24,1,MATCH($B$3,'Savings comparison'!$C$4:$F$4,0))/12+COLUMN(C6:N6)*0,"")}
A12: Car depreciation | B12: Selected option | C12: {=IFERROR(INDEX('Savings comparison'!$C$26:$F$26,1,MATCH($B$3,'Savings comparison'!$C$4:$F$4,0))/12+COLUMN(C6:N6)*0,"")}
A13: Pension reserve contribution | B13: Selected option | C13: {=IFERROR(INDEX('Savings comparison'!$C$27:$F$27,1,MATCH($B$3,'Savings comparison'!$C$4:$F$4,0))/12+COLUMN(C6:N6)*0,"")}
A14: Director fee | B14: Selected option | C14: {=IFERROR(INDEX('Savings comparison'!$C$28:$F$28,1,MATCH($B$3,'Savings comparison'!$C$4:$F$4,0))/12+COLUMN(C6:N6)*0,"")}
A15: RB fee | B15: Selected option | C15: {=IFERROR(INDEX('Savings comparison'!$C$19:$F$19,1,MATCH($B$3,'Savings comparison'!$C$4:$F$4,0))/12+COLUMN(C6:N6)*0,"")}
A17: Scenario profit before tax | B17: Calculated | C17: {=IF(COUNTIF('Savings comparison'!$C$4:$F$4,$B$3)=0,0,C8:N8-C9:N9-C11:N11-C12:N12-C13:N13-C14:N14-C15:N15-C16:N16+C10:N10)} -> 0
A18: Estimated corporation tax | B18: Selected rate | C18: {=IF(COUNTIF('Savings comparison'!$C$4:$F$4,$B$3)=0,0,IF(C17:N17>0,C17:N17*INDEX('Savings comparison'!$C$32:$F$32,1,MATCH($B$3,'Savings comparison'!$C$4:$F$4,0)),0))} -> 0
A19: Profit after tax | B19: Calculated | C19: {=IF(COUNTIF('Savings comparison'!$C$4:$F$4,$B$3)=0,0,C17:N17-C18:N18)} -> 0
A21: Notes | B21: Keep this add-on hidden from the client conversation until an option has been selected.

Sheet Services checklist
A1: Services checklist
A2: RB option fee | B2: ='Savings comparison'!C19 -> 500 | C2: ='Savings comparison'!D19 -> 1000 | D2: ='Savings comparison'!E19 -> 1200 | E2: ='Savings comparison'!F19 -> 1600
A3: Standalone DE market value checked - low | B3: =SUMIF(B8:B39,TRUE,$F$8:$F$39) -> 9511 | C3: =SUMIF(C8:C39,TRUE,$F$8:$F$39) -> 17016 | D3: =SUMIF(D8:D39,TRUE,$F$8:$F$39) -> 17516 | E3: =SUMIF(E8:E39,TRUE,$F$8:$F$39) -> 21016
A4: Standalone DE market value checked - mid | B4: =SUMIF(B8:B39,TRUE,$G$8:$G$39) -> 17005 | C4: =SUMIF(C8:C39,TRUE,$G$8:$G$39) -> 31968 | D4: =SUMIF(D8:D39,TRUE,$G$8:$G$39) -> 32968 | E4: =SUMIF(E8:E39,TRUE,$G$8:$G$39) -> 39968
A5: Status: provisional. Source: RB service-list work, user corrections, and public pricing/statutory references checked 2026-06-15. Low/mid estimates include advisory support plus third-party software, filing, and public-authority costs where relevant; review before client reliance.
A7: Service | B7: Option 1 - Basic operating entity | C7: Option 2 - Full optimisation | D7: Option 3 - Pension reserve | E7: Option 4 - IE tax residence | F7: Low-end DE estimate | G7: Mid-end DE estimate | H7: Timing | I7: Basis / cost components | J7: Linked explanation | K7: RB / client discussion point
A8: Basic operating entity review | B8: TRUE | C8: TRUE | D8: TRUE | E8: TRUE | F8: 824 | G8: 1223 | H8: One-off | I8: Initial entity and accounting review; low uses public tax-advice plus basic support, mid includes deeper bookkeeping/accounting scoping | J8: =HYPERLINK("https://www.firma.de/beratung-steuerberater/","firma.de tax-advice benchmark plus professional-support estimate") -> firma.de tax-advice benchmark plus professional-support estimate | K8: Confirm entity status quo, previous accounting fee, current accountant, and whether the entity is already operational
A9: Company incorporation and compliance approval | B9: TRUE | C9: TRUE | D9: TRUE | E9: TRUE | F9: 900 | G9: 1500 | H9: One-off | I9: One-off incorporation/compliance support estimate; public documents/legal review plus accounting setup oversight | J9: =HYPERLINK("https://www.firma.de/satzung/","firma.de company-document benchmark plus incorporation support estimate") -> firma.de company-document benchmark plus incorporation support estimate | K9: Review whether a new company or operating entity approval is needed before using the template
A10: Client records, document intake and onboarding handover | B10: TRUE | C10: TRUE | D10: TRUE | E10: TRUE | F10: 300 | G10: 600 | H10: One-off | I10: One-off intake estimate for source documents, records, opening balances, access, and handover into recurring operations | J10: =HYPERLINK("https://www.gesetze-im-internet.de/stbgebv/BJNR014420981.html","StBVV-style time-fee benchmark for document intake and admin support") -> StBVV-style time-fee benchmark for document intake and admin support | K10: Collect contracts, prior filings, bank records, payroll records, authority letters, and current fee data
A11: Monthly bookkeeping/accounting package | B11: TRUE | C11: TRUE | D11: TRUE | E11: TRUE | F11: 1368 | G11: 2208 | H11: Annual | I11: Recurring accounting package; low uses 99/month plus DATEV 15/month, mid uses 169/month plus DATEV 15/month | J11: =HYPERLINK("https://www.firma.de/buchhaltung/","firma.de bookkeeping package prices including DATEV software add-on") -> firma.de bookkeeping package prices including DATEV software add-on | K11: Bookkeeping is a recurring operating service, not a one-off advisory line
A12: Bookkeeping software setup and filing calendar setup | B12: TRUE | C12: TRUE | D12: TRUE | E12: TRUE | F12: 300 | G12: 600 | H12: One-off setup | I12: Software setup, chart of accounts, filing calendar, access permissions, and recurring tool configuration; excludes monthly bookkeeping above | J12: =HYPERLINK("https://www.lexware.de/preise/","Lexware Office software prices used where a tool cost is needed") -> Lexware Office software prices used where a tool cost is needed | K12: Make the operating calendar and software stack explicit before the client chooses the option
A13: VAT compliance / VAT filings | B13: TRUE | C13: TRUE | D13: TRUE | E13: TRUE | F13: 600 | G13: 1200 | H13: Annual | I13: Recurring VAT filing support plus filing-software/transmission setup where needed; low assumes lighter filing volume, mid assumes monthly complexity | J13: =HYPERLINK("https://www.lexware.de/preise/","Lexware VAT filing and software-pricing reference for tool costs") -> Lexware VAT filing and software-pricing reference for tool costs | K13: Track VAT deadlines, prepare filings, submit returns, and retain filing/payment evidence
A14: Annual accounts and corporate tax filings | B14: TRUE | C14: TRUE | D14: TRUE | E14: TRUE | F14: 1348 | G14: 2048 | H14: Annual | I14: Annual accounts plus disclosure/filing; low uses 1249 plus 99 disclosure, mid uses 1949 plus 99 disclosure | J14: =HYPERLINK("https://www.firma.de/jahresabschluss-kapitalgesellschaft/","firma.de annual accounts prices plus disclosure filing add-on") -> firma.de annual accounts prices plus disclosure filing add-on | K14: Annual compliance is separate from monthly bookkeeping and should stay visible in the service comparison
A15: Payroll for one employee | B15: TRUE | C15: TRUE | D15: TRUE | E15: TRUE | F15: 240 | G15: 395 | H15: Annual | I15: Recurring payroll plus payroll-software/filing component; low uses payroll service benchmark, mid adds Lexware payroll add-on at 12.90/month | J15: =HYPERLINK("https://www.firma.de/lohnabrechnung/","firma.de payroll benchmark; mid estimate also includes payroll tool cost") -> firma.de payroll benchmark; mid estimate also includes payroll tool cost | K15: Run payroll, social-insurance and wage-tax filings, payments, and evidence capture for the employee
A16: Payroll setup, retroactive payslips and filings | B16: TRUE | C16: TRUE | D16: TRUE | E16: TRUE | F16: 500 | G16: 1000 | H16: One-off / catch-up | I16: Setup or correction project for payroll history, retroactive payslips, registrations, filings and payment reconciliation | J16: =HYPERLINK("https://www.lexware.de/preise/","Lexware payroll filing/tool reference plus setup-support estimate") -> Lexware payroll filing/tool reference plus setup-support estimate | K16: Use when payroll history or late setup needs correction before monthly operation is clean
A17: Office rent / company-address optimisation | B17: FALSE | C17: TRUE | D17: TRUE | E17: TRUE | F17: 1200 | G17: 2400 | H17: Annual recurring | I17: Advisory plus benchmark analysis, company/person rent contract, and recurring monthly rent payment administration | J17: =HYPERLINK("https://www.gesetze-im-internet.de/stbgebv/BJNR014420981.html","Professional time-fee benchmark for rent analysis, contract and recurring payment work") -> Professional time-fee benchmark for rent analysis, contract and recurring payment work | K17: Advise, benchmark the office rent, prepare the contract, and pay the rent every month as agreed
A18: Business travel and expense policy optimisation | B18: FALSE | C18: TRUE | D18: TRUE | E18: TRUE | F18: 900 | G18: 1800 | H18: Annual recurring | I18: Recurring travel policy, per diem calculation, receipt review, reimbursement calculation, company payment, and evidence tracking | J18: =HYPERLINK("https://www.gesetze-im-internet.de/stbgebv/BJNR014420981.html","Professional time-fee benchmark for recurring expense and travel-support work") -> Professional time-fee benchmark for recurring expense and travel-support work | K18: Help the client organise correctly, calculate per diem amounts, track expenses, and reimburse from the company
A19: AP/AR (invoice generation, expense payment, chasing, logging) | B19: FALSE | C19: TRUE | D19: TRUE | E19: TRUE | F19: 1355 | G19: 2663 | H19: Annual recurring | I19: Recurring invoice generation, expense payment, chasing, logging and evidence matching; includes bookkeeping/payment software component | J19: =HYPERLINK("https://www.lexware.de/preise/","Lexware invoicing, banking, payment and bookkeeping tool-cost reference") -> Lexware invoicing, banking, payment and bookkeeping tool-cost reference | K19: Operate invoices, supplier payments, client chasing and evidence logs instead of only advising once
A20: Tax prepayments and tax payments tracking | B20: TRUE | C20: TRUE | D20: TRUE | E20: TRUE | F20: 600 | G20: 1200 | H20: Annual recurring | I20: Recurring tracking of tax prepayment notices, payment due dates, cash planning, executing payments, and storing payment evidence | J20: =HYPERLINK("https://www.gesetze-im-internet.de/stbgebv/BJNR014420981.html","StBVV-style recurring support benchmark for tax-payment tracking") -> StBVV-style recurring support benchmark for tax-payment tracking | K20: Actively track and pay tax prepayments; this is ongoing company-order work, not a one-off log
A21: Tax registration, letters and Finanzamt correspondence | B21: TRUE | C21: TRUE | D21: TRUE | E21: TRUE | F21: 900 | G21: 1800 | H21: Annual recurring | I21: Recurring registration management plus active reading, classification and actioning of tax letters, deadlines, objections and notices | J21: =HYPERLINK("https://www.firma.de/beratung-steuerberater/","Tax-advice benchmark for correspondence support and authority letters") -> Tax-advice benchmark for correspondence support and authority letters | K21: Read tax letters, respond where needed, and keep the company in order before penalties arise
A22: Authority, health insurer and penalty/fine resolution | B22: TRUE | C22: TRUE | D22: TRUE | E22: TRUE | F22: 750 | G22: 1500 | H22: Case-based | I22: Active case management: calls, letters, objections, escalation and chasing with Finanzamt, health insurers, payroll/social bodies and fine issuers | J22: =HYPERLINK("https://www.gesetze-im-internet.de/stbgebv/BJNR014420981.html","Professional time-fee benchmark for authority correspondence and case work") -> Professional time-fee benchmark for authority correspondence and case work | K22: Call Finanzamt and health insurers, fight fines, and keep issue ownership until resolved
A23: Car purchase / depreciation planning | B23: FALSE | C23: TRUE | D23: TRUE | E23: TRUE | F23: 350 | G23: 700 | H23: One-off planning | I23: Vehicle purchase, depreciation, benefit-in-kind and accounting treatment analysis; support estimate only, no vehicle cost included | J23: =HYPERLINK("https://www.gesetze-im-internet.de/stbgebv/BJNR014420981.html","Professional benchmark for depreciation and tax-planning analysis") -> Professional benchmark for depreciation and tax-planning analysis | K23: Analyse car purchase and depreciation treatment before committing to the company purchase
A24: Investment / retained-profit planning | B24: FALSE | C24: TRUE | D24: TRUE | E24: TRUE | F24: 350 | G24: 700 | H24: One-off planning | I24: Retained-profit investment planning and accounting/tax treatment review; advisory support estimate, not investment-management fees | J24: =HYPERLINK("https://www.firma.de/beratung-steuerberater/","Tax-advice benchmark for retained-profit and investment planning") -> Tax-advice benchmark for retained-profit and investment planning | K24: Help decide whether retained profits should be invested or held for taxes, salary and reserve planning
A25: Investment account setup | B25: FALSE | C25: TRUE | D25: TRUE | E25: TRUE | F25: 250 | G25: 500 | H25: One-off setup | I25: Administrative setup estimate for investment account documents, evidence, accounting treatment and source-record workflow | J25: =HYPERLINK("https://www.gesetze-im-internet.de/stbgebv/BJNR014420981.html","Professional support benchmark for setup and evidence handling") -> Professional support benchmark for setup and evidence handling | K25: Set up the investment-account records correctly if the client decides to invest retained profits
A26: Pension reserve planning | B26: FALSE | C26: FALSE | D26: TRUE | E26: FALSE | F26: 500 | G26: 1000 | H26: One-off planning | I26: Additional pension reserve analysis and documentation; reflected as the separate RB pension surcharge line in option 3 | J26: =HYPERLINK("https://www.firma.de/beratung-steuerberater/","Tax-advice benchmark for pension reserve planning support") -> Tax-advice benchmark for pension reserve planning support | K26: Only included when the client chooses the pension reserve add-on
A27: Dual tax jurisdiction / IE-DE tax residence review | B27: FALSE | C27: FALSE | D27: FALSE | E27: TRUE | F27: 1000 | G27: 2000 | H27: One-off review | I27: Cross-border tax-residence review and dual-jurisdiction coordination estimate; excludes actual director service below | J27: =HYPERLINK("https://www.gesetze-im-internet.de/stbgebv/BJNR014420981.html","Professional benchmark for complex cross-border tax and accounting work") -> Professional benchmark for complex cross-border tax and accounting work | K27: Use for IE tax residence structures, not because a person is IE resident
A28: Director fee planning / director-service structuring and board governance | B28: FALSE | C28: FALSE | D28: FALSE | E28: TRUE | F28: 3000 | G28: 6000 | H28: Annual recurring | I28: Recurring actual director service plus board governance, board meetings, minutes, statutory decisions and keeping the company in order | J28: =HYPERLINK("https://www.irishstatutebook.ie/eli/2014/act/38/section/137/enacted/en/html","Irish Companies Act director-residence reference plus annual director-service estimate") -> Irish Companies Act director-residence reference plus annual director-service estimate | K28: This is an actual director required to operate governance and board meetings, not just fee advice
A29: Employer number, accident insurance and VBG registrations | B29: TRUE | C29: TRUE | D29: TRUE | E29: TRUE | F29: 300 | G29: 600 | H29: One-off setup | I29: Employer-number and statutory employer registration support, accident-insurance/VBG routing, and recurring records handover into payroll | J29: =HYPERLINK("https://www.arbeitsagentur.de/unternehmen/betriebsnummern-service","Bundesagentur employer-number service plus employer registration support estimate") -> Bundesagentur employer-number service plus employer registration support estimate | K29: Handle employer registrations and keep the payroll compliance file current
A30: Local business registration (Gewerbeanmeldung) | B30: TRUE | C30: TRUE | D30: TRUE | E30: TRUE | F30: 281 | G30: 531 | H30: One-off | I30: Public fee plus support estimate; Berlin reference shows 31 legal-person filing fee, added to 250/500 support estimate | J30: =HYPERLINK("https://service.berlin.de/dienstleistung/121921/","Berlin Gewerbeanmeldung fee reference plus registration support estimate") -> Berlin Gewerbeanmeldung fee reference plus registration support estimate | K30: Handle local business registration where required and keep registration evidence in the file
A31: Bank account setup | B31: FALSE | C31: TRUE | D31: TRUE | E31: TRUE | F31: 250 | G31: 500 | H31: One-off setup | I31: Administrative setup estimate for bank account opening, access, evidence, mandate and accounting workflow; bank fees not included | J31: =HYPERLINK("https://www.gesetze-im-internet.de/stbgebv/BJNR014420981.html","Professional support benchmark for bank-account setup and records") -> Professional support benchmark for bank-account setup and records | K31: Support bank-account setup and capture records for accounting and payments
A32: Service agreement contracts with client customers | B32: FALSE | C32: TRUE | D32: TRUE | E32: TRUE | F32: 600 | G32: 1200 | H32: One-off / contract | I32: Contract preparation/review support estimate for customer service agreements and accounting/legal alignment | J32: =HYPERLINK("https://www.firma.de/beratung-anwalt/","Legal-consultation benchmark for service agreement support") -> Legal-consultation benchmark for service agreement support | K32: Prepare or review service agreements between the company and its customers
A33: Employment contract changes | B33: FALSE | C33: TRUE | D33: TRUE | E33: TRUE | F33: 500 | G33: 1000 | H33: One-off / change | I33: Employment/director contract change support plus payroll/accounting alignment and recurring payroll handover | J33: =HYPERLINK("https://www.firma.de/beratung-anwalt/","Legal-consultation benchmark for employment contract change support") -> Legal-consultation benchmark for employment contract change support | K33: Change employment or director contracts and align payroll/accounting treatment
A34: Share subscription agreements | B34: FALSE | C34: TRUE | D34: TRUE | E34: TRUE | F34: 650 | G34: 1300 | H34: One-off / document | I34: Share subscription agreement support estimate, including legal document review and company-record alignment | J34: =HYPERLINK("https://www.firma.de/satzung/","Company-document benchmark for shareholder/subscription document support") -> Company-document benchmark for shareholder/subscription document support | K34: Prepare share subscription agreements where the structure needs them
A35: RBO / beneficial-owner filing where applicable | B35: TRUE | C35: TRUE | D35: TRUE | E35: TRUE | F35: 300 | G35: 600 | H35: Annual / event-based | I35: Beneficial-owner filing and annual/trigger-event monitoring support; checked in all options for IE company structures | J35: =HYPERLINK("https://rbo.gov.ie/","RBO Ireland official filing route for relevant Irish incorporated entities") -> RBO Ireland official filing route for relevant Irish incorporated entities | K35: All IE company structures need beneficial-owner filing work, so this is included across plans
A36: Personal tax bookkeeping and filing add-on | B36: FALSE | C36: FALSE | D36: FALSE | E36: FALSE | F36: 750 | G36: 1500 | H36: Optional annual | I36: Optional annual personal tax bookkeeping and filing estimate; separate from company operating entity services | J36: =HYPERLINK("https://www.gesetze-im-internet.de/stbgebv/BJNR014420981.html","StBVV personal tax filing and income-calculation benchmark") -> StBVV personal tax filing and income-calculation benchmark | K36: Optional personal tax support outside the core company option fee
A37: Parental leave planning | B37: FALSE | C37: FALSE | D37: FALSE | E37: FALSE | F37: 450 | G37: 900 | H37: Optional planning | I37: Optional planning estimate for parental leave, owner salary timing, payroll impact and benefit timing | J37: =HYPERLINK("https://www.gesetze-im-internet.de/stbgebv/BJNR014420981.html","Professional support benchmark for parental leave and salary-timing planning") -> Professional support benchmark for parental leave and salary-timing planning | K37: Optional planning for parental leave and owner salary timing
A38: Client forecast and life-change planning | B38: FALSE | C38: TRUE | D38: TRUE | E38: TRUE | F38: 500 | G38: 1000 | H38: Annual / event-based | I38: Recurring annual or event-driven forecast updates after life/business changes; support estimate based on tax/accounting advisory time | J38: =HYPERLINK("https://www.firma.de/beratung-steuerberater/","Tax-advice benchmark for forecast and life-change planning support") -> Tax-advice benchmark for forecast and life-change planning support | K38: Refresh the client forecast for the new year and after material life or business changes
A39: Client calls, inbounds and periodic updates | B39: FALSE | C39: TRUE | D39: TRUE | E39: TRUE | F39: 600 | G39: 1200 | H39: Annual recurring | I39: Recurring client calls, inbound messages, meeting notes, monthly or quarterly updates, and task ownership | J39: =HYPERLINK("https://www.gesetze-im-internet.de/stbgebv/BJNR014420981.html","StBVV-style time-fee benchmark for recurring client support") -> StBVV-style time-fee benchmark for recurring client support | K39: Handle client calls, inbound messages, meeting notes and periodic updates
